Testing backend API at: https://81d95aab-1dcc-45b1-a85e-ac032ba166dc.preview.emergentagent.com/api
‚ùå Stripe checkout session creation test failed: HTTPSConnectionPool(host='81d95aab-1dcc-45b1-a85e-ac032ba166dc.preview.emergentagent.com', port=443): Max retries exceeded with url: /api/payments/checkout/session (Caused by ConnectTimeoutError(<urllib3.connection.HTTPSConnection object at 0xfa707976aed0>, 'Connection to 81d95aab-1dcc-45b1-a85e-ac032ba166dc.preview.emergentagent.com timed out. (connect timeout=None)'))
E
======================================================================
ERROR: test_06_stripe_checkout_session_creation (backend_test.BackendAPITest.test_06_stripe_checkout_session_creation)
Test the creation of a Stripe checkout session
----------------------------------------------------------------------
Traceback (most recent call last):
  File "/root/.venv/lib/python3.11/site-packages/urllib3/connection.py", line 198, in _new_conn
    sock = connection.create_connection(
           ^^^^^^^^^^^^^^^^^^^^^^^^^^^^^
  File "/root/.venv/lib/python3.11/site-packages/urllib3/util/connection.py", line 85, in create_connection
    raise err
  File "/root/.venv/lib/python3.11/site-packages/urllib3/util/connection.py", line 73, in create_connection
    sock.connect(sa)
TimeoutError: [Errno 110] Connection timed out

The above exception was the direct cause of the following exception:

Traceback (most recent call last):
  File "/root/.venv/lib/python3.11/site-packages/urllib3/connectionpool.py", line 787, in urlopen
    response = self._make_request(
               ^^^^^^^^^^^^^^^^^^^
  File "/root/.venv/lib/python3.11/site-packages/urllib3/connectionpool.py", line 488, in _make_request
    raise new_e
  File "/root/.venv/lib/python3.11/site-packages/urllib3/connectionpool.py", line 464, in _make_request
    self._validate_conn(conn)
  File "/root/.venv/lib/python3.11/site-packages/urllib3/connectionpool.py", line 1093, in _validate_conn
    conn.connect()
  File "/root/.venv/lib/python3.11/site-packages/urllib3/connection.py", line 753, in connect
    self.sock = sock = self._new_conn()
                       ^^^^^^^^^^^^^^^^
  File "/root/.venv/lib/python3.11/site-packages/urllib3/connection.py", line 207, in _new_conn
    raise ConnectTimeoutError(
urllib3.exceptions.ConnectTimeoutError: (<urllib3.connection.HTTPSConnection object at 0xfa707976aed0>, 'Connection to 81d95aab-1dcc-45b1-a85e-ac032ba166dc.preview.emergentagent.com timed out. (connect timeout=None)')

The above exception was the direct cause of the following exception:

Traceback (most recent call last):
  File "/root/.venv/lib/python3.11/site-packages/requests/adapters.py", line 667, in send
    resp = conn.urlopen(
           ^^^^^^^^^^^^^
  File "/root/.venv/lib/python3.11/site-packages/urllib3/connectionpool.py", line 841, in urlopen
    retries = retries.increment(
              ^^^^^^^^^^^^^^^^^^
  File "/root/.venv/lib/python3.11/site-packages/urllib3/util/retry.py", line 519, in increment
    raise MaxRetryError(_pool, url, reason) from reason  # type: ignore[arg-type]
    ^^^^^^^^^^^^^^^^^^^^^^^^^^^^^^^^^^^^^^^^^^^^^^^^^^^
urllib3.exceptions.MaxRetryError: HTTPSConnectionPool(host='81d95aab-1dcc-45b1-a85e-ac032ba166dc.preview.emergentagent.com', port=443): Max retries exceeded with url: /api/payments/checkout/session (Caused by ConnectTimeoutError(<urllib3.connection.HTTPSConnection object at 0xfa707976aed0>, 'Connection to 81d95aab-1dcc-45b1-a85e-ac032ba166dc.preview.emergentagent.com timed out. (connect timeout=None)'))

During handling of the above exception, another exception occurred:

Traceback (most recent call last):
  File "/app/backend_test.py", line 136, in test_06_stripe_checkout_session_creation
    response = requests.post(f"{API_URL}/payments/checkout/session", json=payload)
               ^^^^^^^^^^^^^^^^^^^^^^^^^^^^^^^^^^^^^^^^^^^^^^^^^^^^^^^^^^^^^^^^^^^
  File "/root/.venv/lib/python3.11/site-packages/requests/api.py", line 115, in post
    return request("post", url, data=data, json=json, **kwargs)
           ^^^^^^^^^^^^^^^^^^^^^^^^^^^^^^^^^^^^^^^^^^^^^^^^^^^^
  File "/root/.venv/lib/python3.11/site-packages/requests/api.py", line 59, in request
    return session.request(method=method, url=url, **kwargs)
           ^^^^^^^^^^^^^^^^^^^^^^^^^^^^^^^^^^^^^^^^^^^^^^^^^
  File "/root/.venv/lib/python3.11/site-packages/requests/sessions.py", line 589, in request
    resp = self.send(prep, **send_kwargs)
           ^^^^^^^^^^^^^^^^^^^^^^^^^^^^^^
  File "/root/.venv/lib/python3.11/site-packages/requests/sessions.py", line 703, in send
    r = adapter.send(request, **kwargs)
        ^^^^^^^^^^^^^^^^^^^^^^^^^^^^^^^
  File "/root/.venv/lib/python3.11/site-packages/requests/adapters.py", line 688, in send
    raise ConnectTimeout(e, request=request)
requests.exceptions.ConnectTimeout: HTTPSConnectionPool(host='81d95aab-1dcc-45b1-a85e-ac032ba166dc.preview.emergentagent.com', port=443): Max retries exceeded with url: /api/payments/checkout/session (Caused by ConnectTimeoutError(<urllib3.connection.HTTPSConnection object at 0xfa707976aed0>, 'Connection to 81d95aab-1dcc-45b1-a85e-ac032ba166dc.preview.emergentagent.com timed out. (connect timeout=None)'))

----------------------------------------------------------------------
Ran 1 test in 134.725s

FAILED (errors=1)
